<?xml version="1.0" encoding="utf-8"?>
<!-- This URDF was automatically created by SolidWorks to URDF Exporter! Originally created by Stephen Brawner (brawner@gmail.com) 
     Commit Version: 1.6.0-1-g15f4949  Build Version: 1.6.7594.29634
     For more information, please see http://wiki.ros.org/sw_urdf_exporter -->
<robot
  name="UR3.1">
  <link
    name="base_link">
    <inertial>
      <origin
        xyz="3.8795E-05 0.04622 0.00080904"
        rpy="0 0 0" />
      <mass
        value="0.61577" />
      <inertia
        ixx="0.00076128"
        ixy="3.5088E-07"
        ixz="-3.0273E-07"
        iyy="0.0010029"
        iyz="3.469E-06"
        izz="0.00077456" />
    </inertial>
    <visual>
      <origin
        xyz="0 0 0"
        rpy="0 0 0" />
      <geometry>
        <mesh
          filename="package://UR3.1/meshes/base_link.STL" />
      </geometry>
      <material
        name="">
        <color
          rgba="0.89804 0.91765 0.92941 1" />
      </material>
    </visual>
    <collision>
      <origin
        xyz="0 0 0"
        rpy="0 0 0" />
      <geometry>
        <mesh
          filename="package://UR3.1/meshes/base_link.STL" />
      </geometry>
    </collision>
  </link>
  <link
    name="Link1">
    <inertial>
      <origin
        xyz="-6.72257912203408E-06 0.0559386765855418 0.00733659459348494"
        rpy="0 0 0" />
      <mass
        value="0.755970144616532" />
      <inertia
        ixx="0.00106902654454233"
        ixy="-9.435016846572E-08"
        ixz="1.04110007558327E-07"
        iyy="0.000906561198443075"
        iyz="-0.00013105990532095"
        izz="0.000990192718725811" />
    </inertial>
    <visual>
      <origin
        xyz="0 0 0"
        rpy="0 0 0" />
      <geometry>
        <mesh
          filename="package://UR3.1/meshes/Link1.STL" />
      </geometry>
      <material
        name="">
        <color
          rgba="0.792156862745098 0.819607843137255 0.933333333333333 1" />
      </material>
    </visual>
    <collision>
      <origin
        xyz="0 0 0"
        rpy="0 0 0" />
      <geometry>
        <mesh
          filename="package://UR3.1/meshes/Link1.STL" />
      </geometry>
    </collision>
  </link>
  <joint
    name="joint1"
    type="revolute">
    <origin
      xyz="0 0 0.0844"
      rpy="1.5708 0 -3.1416" />
    <parent
      link="base_link" />
    <child
      link="Link1" />
    <axis
      xyz="0 1 0" />
    <limit
      lower="-3.14"
      upper="3.14"
      effort="100"
      velocity="1" />
  </joint>
  <link
    name="Link2">
    <inertial>
      <origin
        xyz="-2.44304282888834E-06 0.064246275556082 0.105690534180816"
        rpy="0 0 0" />
      <mass
        value="1.80196467316198" />
      <inertia
        ixx="0.00264976874313058"
        ixy="-9.2141487717782E-08"
        ixz="1.05534977283353E-07"
        iyy="0.00251744327389939"
        iyz="-8.11001568779186E-05"
        izz="0.00167005885482448" />
    </inertial>
    <visual>
      <origin
        xyz="0 0 0"
        rpy="0 0 0" />
      <geometry>
        <mesh
          filename="package://UR3.1/meshes/Link2.STL" />
      </geometry>
      <material
        name="">
        <color
          rgba="0.792156862745098 0.819607843137255 0.933333333333333 1" />
      </material>
    </visual>
    <collision>
      <origin
        xyz="0 0 0"
        rpy="0 0 0" />
      <geometry>
        <mesh
          filename="package://UR3.1/meshes/Link2.STL" />
      </geometry>
    </collision>
  </link>
  <joint
    name="joint2"
    type="revolute">
    <origin
      xyz="0 0.0675 0.05235"
      rpy="1.5708 0 -3.1416" />
    <parent
      link="Link1" />
    <child
      link="Link2" />
    <axis
      xyz="0 -1 0" />
    <limit
      lower="-3.14"
      upper="3.14"
      effort="100"
      velocity="1" />
  </joint>
  <link
    name="Link3">
    <inertial>
      <origin
        xyz="-0.0051483 -0.11117 -6.589E-07"
        rpy="0 0 0" />
      <mass
        value="0.96243" />
      <inertia
        ixx="0.001015"
        ixy="4.6189E-05"
        ixz="1.2591E-08"
        iyy="0.0005428"
        iyz="-8.3435E-09"
        izz="0.0010729" />
    </inertial>
    <visual>
      <origin
        xyz="0 0 0"
        rpy="0 0 0" />
      <geometry>
        <mesh
          filename="package://UR3.1/meshes/Link3.STL" />
      </geometry>
      <material
        name="">
        <color
          rgba="1 1 1 1" />
      </material>
    </visual>
    <collision>
      <origin
        xyz="0 0 0"
        rpy="0 0 0" />
      <geometry>
        <mesh
          filename="package://UR3.1/meshes/Link3.STL" />
      </geometry>
    </collision>
  </link>
  <joint
    name="joint3"
    type="revolute">
    <origin
      xyz="0 -0.02535 0.24365"
      rpy="-1.5708 0 -1.5708" />
    <parent
      link="Link2" />
    <child
      link="Link3" />
    <axis
      xyz="1 0 0" />
    <limit
      lower="-3.14"
      upper="3.14"
      effort="100"
      velocity="1" />
  </joint>
  <link
    name="Link4">
    <inertial>
      <origin
        xyz="0.0059214 -0.0005174 1.4077E-07"
        rpy="0 0 0" />
      <mass
        value="0.32522" />
      <inertia
        ixx="0.00019461"
        ixy="1.8339E-05"
        ixz="2.5704E-10"
        iyy="0.00019911"
        iyz="7.6631E-10"
        izz="0.00022621" />
    </inertial>
    <visual>
      <origin
        xyz="0 0 0"
        rpy="0 0 0" />
      <geometry>
        <mesh
          filename="package://UR3.1/meshes/Link4.STL" />
      </geometry>
      <material
        name="">
        <color
          rgba="1 1 1 1" />
      </material>
    </visual>
    <collision>
      <origin
        xyz="0 0 0"
        rpy="0 0 0" />
      <geometry>
        <mesh
          filename="package://UR3.1/meshes/Link4.STL" />
      </geometry>
    </collision>
  </link>
  <joint
    name="joint4"
    type="revolute">
    <origin
      xyz="-0.0834 -0.213 0"
      rpy="-3.1416 0 0" />
    <parent
      link="Link3" />
    <child
      link="Link4" />
    <axis
      xyz="1 0 0" />
    <limit
      lower="-3.14"
      upper="3.14"
      effort="100"
      velocity="1" />
  </joint>
  <link
    name="Link5">
    <inertial>
      <origin
        xyz="0.00592139514298895 0.000517400306516258 -1.69757060907155E-07"
        rpy="0 0 0" />
      <mass
        value="0.325224003187047" />
      <inertia
        ixx="0.000194604977488079"
        ixy="-1.83387919982607E-05"
        ixz="-2.70364349647352E-10"
        iyy="0.000199105679234156"
        iyz="8.25448953543642E-10"
        izz="0.000226212705078878" />
    </inertial>
    <visual>
      <origin
        xyz="0 0 0"
        rpy="0 0 0" />
      <geometry>
        <mesh
          filename="package://UR3.1/meshes/Link5.STL" />
      </geometry>
      <material
        name="">
        <color
          rgba="1 1 1 1" />
      </material>
    </visual>
    <collision>
      <origin
        xyz="0 0 0"
        rpy="0 0 0" />
      <geometry>
        <mesh
          filename="package://UR3.1/meshes/Link5.STL" />
      </geometry>
    </collision>
  </link>
  <joint
    name="joint5"
    type="revolute">
    <origin
      xyz="0 0.0834 0"
      rpy="0 0 -1.5708" />
    <parent
      link="Link4" />
    <child
      link="Link5" />
    <axis
      xyz="-1 0 0" />
    <limit
      lower="-3.14"
      upper="3.14"
      effort="100"
      velocity="1" />
  </joint>
  <link
    name="Link6">
    <inertial>
      <origin
        xyz="-1.4879E-10 0.00010329 -0.021073"
        rpy="0 0 0" />
      <mass
        value="0.11536" />
      <inertia
        ixx="4.2472E-05"
        ixy="-7.1197E-13"
        ixz="1.8571E-12"
        iyy="4.2687E-05"
        iyz="1.0322E-07"
        izz="5.9069E-05" />
    </inertial>
    <visual>
      <origin
        xyz="0 0 0"
        rpy="0 0 0" />
      <geometry>
        <mesh
          filename="package://UR3.1/meshes/Link6.STL" />
      </geometry>
      <material
        name="">
        <color
          rgba="1 1 1 1" />
      </material>
    </visual>
    <collision>
      <origin
        xyz="0 0 0"
        rpy="0 0 0" />
      <geometry>
        <mesh
          filename="package://UR3.1/meshes/Link6.STL" />
      </geometry>
    </collision>
  </link>
  <joint
    name="joint6"
    type="revolute">
    <origin
      xyz="0 -0.0409 0"
      rpy="1.5708 -1.5708 0" />
    <parent
      link="Link5" />
    <child
      link="Link6" />
    <axis
      xyz="0 0 1" />
    <limit
      lower="-3.14"
      upper="3.14"
      effort="100"
      velocity="1" />
  </joint>
</robot>